Workbook

Sheet Benchmarks
A1: S&P 500
A2: Ticker | B2: Weight | C2: Return | D2: Total Return
A3: VOO | B3: 1 | C3: {=_xll.YCP(A3,"roc_1")} -> 0.0046816032 | D3: =B3*C3 -> 0.0046816032
D4: =SUM(D3:D3) -> 0.0046816032
A6: Dow Jones Industrial Average
A7: Ticker | B7: Weight | C7: Return | D7: Total Return
A8: DIA | B8: 1 | C8: {=_xll.YCP(A8,"roc_1")} -> 0.002278915 | D8: =B8*C8 -> 0.002278915
D9: =SUM(D8:D8) -> 0.002278915
A11: Nasdaq 100
A12: Ticker | B12: Weight | C12: Return | D12: Total Return
A13: QQQ | B13: 1 | C13: {=_xll.YCP(A13,"roc_1")} -> 0.0069848661 | D13: =B13*C13 -> 0.0069848661
D14: =SUM(D13:D13) -> 0.0069848661
A16: U.S. Bonds
A17: Ticker | B17: Weight | C17: Return | D17: Total Return
A18: AGG | B18: 1 | C18: {=_xll.YCP(A18,"roc_1")} -> -0.0013861386 | D18: =B18*C18 -> -0.0013861386
D19: =SUM(D18:D18) -> -0.0013861386
A21: U.S. Dollar
A22: Ticker | B22: Weight | C22: Return | D22: Total Return
A23: UUP | B23: 1 | C23: {=_xll.YCP(A23,"roc_1")} -> 0.0059457451 | D23: =B23*C23 -> 0.0059457451
D24: =SUM(D23:D23) -> 0.0059457451
A26: Commodities
A27: Ticker | B27: Weight | C27: Return | D27: Total Return
A28: PDBC | B28: 1 | C28: {=_xll.YCP(A28,"roc_1")} -> 0.026728439 | D28: =B28*C28 -> 0.026728439
D29: =SUM(D28:D28) -> 0.026728439

Sheet NelsonCorp
A1: MODERATE
A2: Ticker | B2: Weight | C2: Return | D2: Total Return | E2: ="+/- Benchmark" -> +/- Benchmark
A3: CASH | B3: 0.02 | C3: {=_xll.YCP("M:FZFXX","roc_1")} -> 9.2e-05 | D3: =B3*C3 -> 1.84e-06
A4: TLT | B4: 0.0567 | C4: {=_xll.YCP(A4,"roc_1")} -> -0.0037832425 | D4: =B4*C4 -> -0.00021450985
A5: USHY | B5: 0.0567 | C5: {=_xll.YCP(A5,"roc_1")} -> 0.0020032051 | D5: =B5*C5 -> 0.00011358173
A6: TIP | B6: 0.0567 | C6: {=_xll.YCP(A6,"roc_1")} -> -0.00076418232 | D6: =B6*C6 -> -4.3329138e-05
A7: VTI | B7: 0.1575 | C7: {=_xll.YCP(A7,"roc_1")} -> 0.0052659685 | D7: =B7*C7 -> 0.00082939004
A8: SPHB | B8: 0.0481 | C8: {=_xll.YCP(A8,"roc_1")} -> 0.010980966 | D8: =B8*C8 -> 0.00052818448
A9: XLK | B9: 0.0481 | C9: {=_xll.YCP(A9,"roc_1")} -> 0.010324061 | D9: =B9*C9 -> 0.00049658732
A10: AMLP | B10: 0.0481 | C10: {=_xll.YCP(A10,"roc_1")} -> 0.0035999222 | D10: =B10*C10 -> 0.00017315626
A11: SPMO | B11: 0.0481 | C11: {=_xll.YCP(A11,"roc_1")} -> 0.0038700993 | D11: =B11*C11 -> 0.00018615178
A12: VEA | B12: 0.06 | C12: {=_xll.YCP(A12,"roc_1")} -> 0.0033537474 | D12: =B12*C12 -> 0.00020122485
A13: VWO | B13: 0.06 | C13: {=_xll.YCP(A13,"roc_1")} -> 0.0025956048 | D13: =B13*C13 -> 0.00015573629
A14: DIA | B14: 0.1307 | C14: {=_xll.YCP(A14,"roc_1")} -> 0.002278915 | D14: =B14*C14 -> 0.00029785419
A15: QQQM | B15: 0.056 | C15: {=_xll.YCP(A15,"roc_1")} -> 0.0070283152 | D15: =B15*C15 -> 0.00039358565
... A17: SFLR | B17: 0.06 | C17: {=_xll.YCP(A17,"roc_1")} -> 0.0049153468 | D17: =B17*C17 -> 0.00029492081
B18: =SUM(B3:B17) -> 1 | D18: =SUM(D3:D17) -> 0.0038905726 | E18: =D18-Benchmarks!$D$4 -> -0.00079103062
A20: ABS RTN MODERATE
A21: Ticker | B21: Weight | C21: Return | D21: Total Return | E21: ="+/- Benchmark" -> +/- Benchmark
A22: CASH | B22: 0.01 | C22: {=_xll.YCP("M:FZFXX","roc_1")} -> 9.2e-05 | D22: =B22*C22 -> 9.2e-07
A23: TLT | B23: 0.0367 | C23: {=_xll.YCP(A23,"roc_1")} -> -0.0037832425 | D23: =B23*C23 -> -0.000138845
A24: USHY | B24: 0.0367 | C24: {=_xll.YCP(A24,"roc_1")} -> 0.0020032051 | D24: =B24*C24 -> 7.3517628e-05
A25: TIP | B25: 0.0367 | C25: {=_xll.YCP(A25,"roc_1")} -> -0.00076418232 | D25: =B25*C25 -> -2.8045491e-05
A26: SPHB | B26: 0.025 | C26: {=_xll.YCP(A26,"roc_1")} -> 0.010980966 | D26: =B26*C26 -> 0.00027452416
A27: XLK | B27: 0.025 | C27: {=_xll.YCP(A27,"roc_1")} -> 0.010324061 | D27: =B27*C27 -> 0.00025810152
A28: AMLP | B28: 0.025 | C28: {=_xll.YCP(A28,"roc_1")} -> 0.0035999222 | D28: =B28*C28 -> 8.9998054e-05
A29: SPMO | B29: 0.025 | C29: {=_xll.YCP(A29,"roc_1")} -> 0.0038700993 | D29: =B29*C29 -> 9.6752482e-05
A30: VEA | B30: 0.0975 | C30: {=_xll.YCP(A30,"roc_1")} -> 0.0033537474 | D30: =B30*C30 -> 0.00032699038
A31: VWO | B31: 0.0975 | C31: {=_xll.YCP(A31,"roc_1")} -> 0.0025956048 | D31: =B31*C31 -> 0.00025307147
A32: DIA | B32: 0.2123 | C32: {=_xll.YCP(A32,"roc_1")} -> 0.002278915 | D32: =B32*C32 -> 0.00048381365
A33: QQQM | B33: 0.091 | C33: {=_xll.YCP(A33,"roc_1")} -> 0.0070283152 | D33: =B33*C33 -> 0.00063957669
A34: SPYM | B34: 0.1516 | C34: {=_xll.YCP(A34,"roc_1")} -> 0.0051039462 | D34: =B34*C34 -> 0.00077375825
... A38: PDBC | B38: 0.04 | C38: {=_xll.YCP(A38,"roc_1")} -> 0.026728439 | D38: =B38*C38 -> 0.0010691376
B39: =SUM(B22:B38) -> 1 | D39: =SUM(D22:D38) -> 0.0038845475 | E39: =D39-Benchmarks!$D$4 -> -0.00079705567
A41: TAX MODERATE
A42: Ticker | B42: Weight | C42: Return | D42: Total Return | E42: ="+/- Benchmark" -> +/- Benchmark
A43: CASH | B43: 0.02 | C43: {=_xll.YCP("M:FZFXX","roc_1")} -> 9.2e-05 | D43: =B43*C43 -> 1.84e-06
A44: BOXX | B44: 0.13 | C44: {=_xll.YCP(A44,"roc_1")} -> -0.00017281604 | D44: =B44*C44 -> -2.2466085e-05
A45: MEAR | B45: 0.06 | C45: {=_xll.YCP(A45,"roc_1")} -> 0.00019778481 | D45: =B45*C45 -> 1.1867089e-05
A46: PFFV | B46: 0.09 | C46: {=_xll.YCP(A46,"roc_1")} -> -0.00044072279 | D46: =B46*C46 -> -3.9665051e-05
...

Sheet Dashboard
A1: Model | C1: Daily | D1: ="+/- Bench" -> +/- Bench | E1: YTD | F1: ="+/- Bench" -> +/- Bench
A2: S&P 500 | C2: =Benchmarks!D4 -> 0.0046816032 | E2: {=_xll.YCP("VOO","ytd_total_return")} -> 0.001371
A3: Dow | C3: =Benchmarks!D9 -> 0.002278915 | E3: {=_xll.YCP("DIA","ytd_total_return")} -> 0.032169
A4: Nasdaq 100 | C4: =Benchmarks!D14 -> 0.0069848661 | E4: {=_xll.YCP("QQQ","ytd_total_return")} -> -0.021178
A5: U.S. Bonds | C5: =Benchmarks!D19 -> -0.0013861386 | E5: {=_xll.YCP("AGG","ytd_total_return")} -> 0.014507
A6: U.S. Dollar | C6: =Benchmarks!D24 -> 0.0059457451 | E6: {=_xll.YCP("UUP","ytd_total_return")} -> -0.00444
A7: Commodities | C7: =Benchmarks!D29 -> 0.026728439 | E7: {=_xll.YCP("PDBC","ytd_total_return")} -> 0.058868
A8: Moderate | C8: =NelsonCorp!D18 -> 0.0038905726 | D8: =NelsonCorp!E18 -> -0.00079103062 | E8: {=_xll.YCP("P:552644","ytd_total_return")} -> 0.007492 | F8: =E8-$E$2 -> 0.006121
A9: Abs Rtn Moderate | C9: =NelsonCorp!D39 -> 0.0038845475 | D9: =NelsonCorp!E39 -> -0.00079705567 | E9: {=_xll.YCP("P:555767","ytd_total_return")} -> 0.011272 | F9: =E9-$E$2 -> 0.009901
A10: Tax Moderate | C10: =NelsonCorp!D54 -> 0.003793063 | D10: =NelsonCorp!E54 -> -0.0008885402 | E10: {=_xll.YCP("P:1146880","ytd_total_return")} -> 0.00152 | F10: =E10-$E$2 -> 0.000149
A11: Aggressive | C11: =NelsonCorp!D70 -> 0.0051226674 | D11: =NelsonCorp!E70 -> 0.00044106416 | E11: {=_xll.YCP("P:597223","ytd_total_return")} -> 0.00698 | F11: =E11-$E$2 -> 0.005609
A12: All Tactical | C12: =NelsonCorp!D81 -> 0.0048522192 | D12: =NelsonCorp!E81 -> 0.00017061597 | E12: {=_xll.YCP("P:1297251","ytd_total_return")} -> -0.000166 | F12: =E12-$E$2 -> -0.001537
A13: Macro | C13: =NelsonCorp!D90 -> 0.0071227445 | D13: =NelsonCorp!E90 -> 0.0024411413 | E13: {=_xll.YCP("P:1729042","ytd_total_return")} -> 0.019548 | F13: =E13-$E$2 -> 0.018177
